Workbook

Sheet Сводка
A1: Entropiq: сводка финансового плана на 12 месяцев
A2: Менять цифры нужно на листе «Допущения». Здесь всё пересчитывается само.
A3: Показатель | B3: Пессимистичный | C3: Базовый | D3: Оптимистичный
A4: Регистрации за год | B4: ='План_Пессимистичный'!N4 -> 1120 | C4: ='План_Базовый'!N4 -> 2200 | D4: ='План_Оптимистичный'!N4 -> 3690
A5: Платящих на конец года | B5: ='План_Пессимистичный'!M7 -> 27 | C5: ='План_Базовый'!M7 -> 132 | D5: ='План_Оптимистичный'!M7 -> 406
A6: Выручка, руб. | B6: ='План_Пессимистичный'!N8 -> 13454.883 | C6: ='План_Базовый'!N8 -> 62811.658 | D6: ='План_Оптимистичный'!N8 -> 182307.01
A7: Расходы, руб. | B7: ='План_Пессимистичный'!N15 -> 35526.737 | C7: ='План_Базовый'!N15 -> 45908.726 | D7: ='План_Оптимистичный'!N15 -> 67254.596
A8: Операционная прибыль, руб. | B8: ='План_Пессимистичный'!N16 -> -22071.853 | C8: ='План_Базовый'!N16 -> 16902.932 | D8: ='План_Оптимистичный'!N16 -> 115052.41
A9: Первоначальные инвестиции, руб. | B9: ='План_Пессимистичный'!N17 -> 12000 | C9: ='План_Базовый'!N17 -> 12000 | D9: ='План_Оптимистичный'!N17 -> 12000
A10: Результат после инвестиций, руб. | B10: ='План_Пессимистичный'!N18 -> -34071.853 | C10: ='План_Базовый'!N18 -> 4902.9319 | D10: ='План_Оптимистичный'!N18 -> 103052.41
A11: ROI = результат после инвестиций / инвестиции | B11: =IF(B9=0, 0, B10/B9) -> -2.8393211 | C11: =IF(C9=0, 0, C10/C9) -> 0.40857766 | D11: =IF(D9=0, 0, D10/D9) -> 8.587701
A12: Маржинальность, % | B12: ='Маржа и безубыточность'!B8 -> 0.972 | C12: ='Маржа и безубыточность'!C8 -> 0.972 | D12: ='Маржа и безубыточность'!D8 -> 0.972
A13: Чистая маржа, % | B13: ='Маржа и безубыточность'!B26 -> -1.6404344 | C13: ='Маржа и безубыточность'!C26 -> 0.26910501 | D13: ='Маржа и безубыточность'!D26 -> 0.63109155
A14: Безубыточность, платящих (мес. 4–12) | B14: ='Маржа и безубыточность'!B14 -> 47 | C14: ='Маржа и безубыточность'!C14 -> 63 | D14: ='Маржа и безубыточность'!D14 -> 94
A15: Месяц окупаемости | B15: ='Маржа и безубыточность'!B20 -> не за 12 мес. | C15: ='Маржа и безубыточность'!C20 -> 11 | D15: ='Маржа и безубыточность'!D20 -> 4
A16: LTV / CAC | B16: ='Маржа и безубыточность'!B31 -> 1.1262594 | C16: ='Маржа и безубыточность'!C31 -> 4.453542 | D16: ='Маржа и безубыточность'!D31 -> 10.012497
A18: Накопленный денежный поток по месяцам, руб.
A19: Месяц | B19: Пессимистичный | C19: Базовый | D19: Оптимистичный
A20: 1 | B20: ='План_Пессимистичный'!B19 -> -14146.797 | C20: ='План_Базовый'!B19 -> -12657.701 | D20: ='План_Оптимистичный'!B19 -> -9614.7659
A21: 2 | B21: ='План_Пессимистичный'!C19 -> -16164.107 | C21: ='План_Базовый'!C19 -> -12797.456 | D21: ='План_Оптимистичный'!C19 -> -5805.1792
A22: 3 | B22: ='План_Пессимистичный'!D19 -> -18051.931 | C22: ='План_Базовый'!D19 -> -12419.264 | D22: ='План_Оптимистичный'!D19 -> -571.2399
A23: 4 | B23: ='План_Пессимистичный'!E19 -> -20175.011 | C23: ='План_Базовый'!E19 -> -12758.382 | D23: ='План_Оптимистичный'!E19 -> 3175.5118
A24: 5 | B24: ='План_Пессимистичный'!F19 -> -22268.605 | C24: ='План_Базовый'!F19 -> -12614.811 | D24: ='План_Оптимистичный'!F19 -> 8764.5625
A25: 6 | B25: ='План_Пессимистичный'!G19 -> -24232.712 | C25: ='План_Базовый'!G19 -> -11823.807 | D25: ='План_Оптимистичный'!G19 -> 16360.656
A26: 7 | B26: ='План_Пессимистичный'!H19 -> -26067.333 | C26: ='План_Базовый'!H19 -> -10514.856 | D26: ='План_Оптимистичный'!H19 -> 25575.331
A27: 8 | B27: ='План_Пессимистичный'!I19 -> -27887.21 | C27: ='План_Базовый'!I19 -> -8673.216 | D27: ='План_Оптимистичный'!I19 -> 36747.049
A28: 9 | B28: ='План_Пессимистичный'!J19 -> -29577.601 | C28: ='План_Базовый'!J19 -> -6248.886 | D28: ='План_Оптимистичный'!J19 -> 49925.809
A29: 10 | B29: ='План_Пессимистичный'!K19 -> -31188.505 | C29: ='План_Базовый'!K19 -> -3227.123 | D29: ='План_Оптимистичный'!K19 -> 65255.841
A30: 11 | B30: ='План_Пессимистичный'!L19 -> -32669.922 | C30: ='План_Базовый'!L19 -> 506.8163 | D30: ='План_Оптимистичный'!L19 -> 82916.632
A31: 12 | B31: ='План_Пессимистичный'!M19 -> -34071.853 | C31: ='План_Базовый'!M19 -> 4902.9319 | D31: ='План_Оптимистичный'!M19 -> 103052.41

Sheet Допущения
A1: Entropiq: финансовый план. Допущения
A2: Синий текст: вводные данные, их можно менять.
A3: Общие параметры | B3: Значение | E3: Комментарий / источник
A4: Цена годовой подписки, руб. | B4: 590 | E4: Цена Premium в проекте (лендинг, условия)
A5: Цена месячной подписки, руб. | B5: 99 | E5: Цена Premium в проекте (ENQ-129)
A6: Доля годовых подписок | B6: 0.65 | E6: Допущение проекта (docs/financial-model.md, п. 1.1)
A7: ARPU, руб. в месяц на платящего | B7: =B6*B4/12+(1-B6)*B5 -> 66.608333 | E7: Формула: доля годовых × цена/12 + доля месячных × цена
A8: Комиссия ЮKassa, % от выручки | B8: 0.028 | E8: Допущение проекта; уточнить по тарифу ЮKassa при подключении
A9: Первоначальные инвестиции, руб. | B9: 12000 | E9: Домен, хостинг на 6 мес., тест рекламы, резерв (бизнес-план)
A10: Хостинг VPS, руб. в месяц | B10: 500 | E10: Допущение проекта
A11: Реклама в мес. 1–3, руб. в месяц | B11: 2000 | E11: Допущение проекта
A13: Параметры сценариев | B13: Пессимистичный | C13: Базовый | D13: Оптимистичный | E13: Комментарий / источник
A14: Доля активных (MAU / регистрации) | B14: 0.3 | C14: 0.4 | D14: 0.5 | E14: Допущение проекта
A15: Конверсия MAU → платящие | B15: 0.08 | C15: 0.15 | D15: 0.22 | E15: Ключевая гипотеза. Проверять на альфа-тесте (ENQ-115, ENQ-116)
A16: Реклама с 4-го месяца, руб. в месяц | B16: 2000 | C16: 3000 | D16: 5000 | E16: Допущение проекта
A17: Отток месячных подписчиков, % в месяц | B17: 0.15 | C17: 0.1 | D17: 0.07 | E17: Используется только в расчёте LTV
A18: Отток годовых подписчиков, % в месяц (экв.) | B18: 0.04 | C18: 0.04 | D18: 0.04 | E18: ≈ 40% не продлевают за год, равномерно по месяцам
A20: Новые регистрации по месяцам | B20: Пессимистичный | C20: Базовый | D20: Оптимистичный | E20: Комментарий
A21: Месяц 1 | B21: 300 | C21: 500 | D21: 700 | E21: Первый месяц включает запуск и приглашения знакомых. Данные из docs/financial-model.md, разд. 3
A22: Месяц 2 | B22: 70 | C22: 130 | D22: 200
A23: Месяц 3 | B23: 70 | C23: 130 | D23: 200
A24: Месяц 4 | B24: 80 | C24: 150 | D24: 250
A25: Месяц 5 | B25: 80 | C25: 160 | D25: 280
A26: Месяц 6 | B26: 80 | C26: 160 | D26: 280
A27: Месяц 7 | B27: 60 | C27: 130 | D27: 230
A28: Месяц 8 | B28: 70 | C28: 150 | D28: 280
A29: Месяц 9 | B29: 70 | C29: 150 | D29: 280
A30: Месяц 10 | B30: 80 | C30: 170 | D30: 310
A31: Месяц 11 | B31: 80 | C31: 180 | D31: 330
A32: Месяц 12 | B32: 80 | C32: 190 | D32: 350
A33: Итого за 12 месяцев | B33: =SUM(B21:B32) -> 1120 | C33: =SUM(C21:C32) -> 2200 | D33: =SUM(D21:D32) -> 3690
A35: Расходы, общие для сценариев | B35: SMS (SMS Aero), руб. | C35: API LLM, руб. | E35: Комментарий
A36: Месяц 1 | B36: 100 | C36: 0 | E36: SMS ≈ 2 руб./сообщение, растёт с регистрациями. LLM: бесплатный лимит в первые 3 месяца
A37: Месяц 2 | B37: 100 | C37: 0
A38: Месяц 3 | B38: 100 | C38: 0
A39: Месяц 4 | B39: 200 | C39: 200
A40: Месяц 5 | B40: 200 | C40: 300
A41: Месяц 6 | B41: 200 | C41: 300
A42: Месяц 7 | B42: 200 | C42: 300
A43: Месяц 8 | B43: 250 | C43: 300
...

Sheet План_Пессимистичный
A1: Помесячный план: Пессимистичный сценарий
A2: Все ячейки считаются формулами из листа «Допущения». Суммы в рублях.
A3: Показатель | B3: Мес. 1 | C3: Мес. 2 | D3: Мес. 3 | E3: Мес. 4 | F3: Мес. 5 | G3: Мес. 6 | H3: Мес. 7 | I3: Мес. 8 | J3: Мес. 9 | K3: Мес. 10 | L3: Мес. 11 | M3: Мес. 12 | N3: Итого / конец
A4: Новые регистрации | B4: ='Допущения'!B21 -> 300 | C4: ='Допущения'!B22 -> 70 | D4: ='Допущения'!B23 -> 70 | E4: ='Допущения'!B24 -> 80 | F4: ='Допущения'!B25 -> 80 | G4: ='Допущения'!B26 -> 80 | H4: ='Допущения'!B27 -> 60 | I4: ='Допущения'!B28 -> 70 | J4: ='Допущения'!B29 -> 70 | K4: ='Допущения'!B30 -> 80 | L4: ='Допущения'!B31 -> 80 | M4: ='Допущения'!B32 -> 80 | N4: =SUM(B4:M4) -> 1120
A5: Всего регистраций | B5: =B4 -> 300 | C5: =B5+C4 -> 370 | D5: =C5+D4 -> 440 | E5: =D5+E4 -> 520 | F5: =E5+F4 -> 600 | G5: =F5+G4 -> 680 | H5: =G5+H4 -> 740 | I5: =H5+I4 -> 810 | J5: =I5+J4 -> 880 | ... M5: =L5+M4 -> 1120 | N5: =M5 -> 1120
A6: MAU (активные) | B6: =ROUND(B5*'Допущения'!B14, 0) -> 90 | C6: =ROUND(C5*'Допущения'!B14, 0) -> 111 | D6: =ROUND(D5*'Допущения'!B14, 0) -> 132 | E6: =ROUND(E5*'Допущения'!B14, 0) -> 156 | F6: =ROUND(F5*'Допущения'!B14, 0) -> 180 | G6: =ROUND(G5*'Допущения'!B14, 0) -> 204 | H6: =ROUND(H5*'Допущения'!B14, 0) -> 222 | I6: =ROUND(I5*'Допущения'!B14, 0) -> 243 | J6: =ROUND(J5*'Допущения'!B14, 0) -> 264 | K6: =ROUND(K5*'Допущения'!B14, 0) -> 288 | L6: =ROUND(L5*'Допущения'!B14, 0) -> 312 | M6: =ROUND(M5*'Допущения'!B14, 0) -> 336 | N6: =M6 -> 336
A7: Платящие пользователи | B7: =ROUND(B6*'Допущения'!B15, 0) -> 7 | C7: =ROUND(C6*'Допущения'!B15, 0) -> 9 | D7: =ROUND(D6*'Допущения'!B15, 0) -> 11 | E7: =ROUND(E6*'Допущения'!B15, 0) -> 12 | F7: =ROUND(F6*'Допущения'!B15, 0) -> 14 | G7: =ROUND(G6*'Допущения'!B15, 0) -> 16 | H7: =ROUND(H6*'Допущения'!B15, 0) -> 18 | I7: =ROUND(I6*'Допущения'!B15, 0) -> 19 | J7: =ROUND(J6*'Допущения'!B15, 0) -> 21 | K7: =ROUND(K6*'Допущения'!B15, 0) -> 23 | L7: =ROUND(L6*'Допущения'!B15, 0) -> 25 | M7: =ROUND(M6*'Допущения'!B15, 0) -> 27 | N7: =M7 -> 27
A8: Выручка | B8: =B7*'Допущения'!$B$7 -> 466.25833 | C8: =C7*'Допущения'!$B$7 -> 599.475 | D8: =D7*'Допущения'!$B$7 -> 732.69167 | E8: =E7*'Допущения'!$B$7 -> 799.3 | F8: =F7*'Допущения'!$B$7 -> 932.51667 | G8: =G7*'Допущения'!$B$7 -> 1065.7333 | H8: =H7*'Допущения'!$B$7 -> 1198.95 | I8: =I7*'Допущения'!$B$7 -> 1265.5583 | ... M8: =M7*'Допущения'!$B$7 -> 1798.425 | N8: =SUM(B8:M8) -> 13454.883
A9: Расходы
A10: Хостинг | B10: ='Допущения'!$B$10 -> 500 | C10: ='Допущения'!$B$10 -> 500 | D10: ='Допущения'!$B$10 -> 500 | E10: ='Допущения'!$B$10 -> 500 | F10: ='Допущения'!$B$10 -> 500 | G10: ='Допущения'!$B$10 -> 500 | H10: ='Допущения'!$B$10 -> 500 | I10: ='Допущения'!$B$10 -> 500 | ... M10: ='Допущения'!$B$10 -> 500 | N10: =SUM(B10:M10) -> 6000
A11: Реклама | B11: =IF(1<=3, 'Допущения'!$B$11, 'Допущения'!B16) -> 2000 | C11: =IF(2<=3, 'Допущения'!$B$11, 'Допущения'!B16) -> 2000 | D11: =IF(3<=3, 'Допущения'!$B$11, 'Допущения'!B16) -> 2000 | E11: =IF(4<=3, 'Допущения'!$B$11, 'Допущения'!B16) -> 2000 | F11: =IF(5<=3, 'Допущения'!$B$11, 'Допущения'!B16) -> 2000 | G11: =IF(6<=3, 'Допущения'!$B$11, 'Допущения'!B16) -> 2000 | H11: =IF(7<=3, 'Допущения'!$B$11, 'Допущения'!B16) -> 2000 | I11: =IF(8<=3, 'Допущения'!$B$11, 'Допущения'!B16) -> 2000 | J11: =IF(9<=3, 'Допущения'!$B$11, 'Допущения'!B16) -> 2000 | K11: =IF(10<=3, 'Допущения'!$B$11, 'Допущения'!B16) -> 2000 | L11: =IF(11<=3, 'Допущения'!$B$11, 'Допущения'!B16) -> 2000 | M11: =IF(12<=3, 'Допущения'!$B$11, 'Допущения'!B16) -> 2000 | N11: =SUM(B11:M11) -> 24000
A12: SMS-верификация | B12: ='Допущения'!B36 -> 100 | C12: ='Допущения'!B37 -> 100 | D12: ='Допущения'!B38 -> 100 | E12: ='Допущения'!B39 -> 200 | F12: ='Допущения'!B40 -> 200 | G12: ='Допущения'!B41 -> 200 | H12: ='Допущения'!B42 -> 200 | I12: ='Допущения'!B43 -> 250 | J12: ='Допущения'!B44 -> 250 | K12: ='Допущения'!B45 -> 300 | L12: ='Допущения'!B46 -> 300 | M12: ='Допущения'!B47 -> 350 | N12: =SUM(B12:M12) -> 2550
A13: API LLM | B13: ='Допущения'!C36 -> 0 | C13: ='Допущения'!C37 -> 0 | D13: ='Допущения'!C38 -> 0 | E13: ='Допущения'!C39 -> 200 | F13: ='Допущения'!C40 -> 300 | G13: ='Допущения'!C41 -> 300 | H13: ='Допущения'!C42 -> 300 | I13: ='Допущения'!C43 -> 300 | J13: ='Допущения'!C44 -> 300 | K13: ='Допущения'!C45 -> 300 | L13: ='Допущения'!C46 -> 300 | M13: ='Допущения'!C47 -> 300 | N13: =SUM(B13:M13) -> 2600
A14: Комиссия ЮKassa | B14: =B8*'Допущения'!$B$8 -> 13.055233 | C14: =C8*'Допущения'!$B$8 -> 16.7853 | D14: =D8*'Допущения'!$B$8 -> 20.515367 | E14: =E8*'Допущения'!$B$8 -> 22.3804 | F14: =F8*'Допущения'!$B$8 -> 26.110467 | G14: =G8*'Допущения'!$B$8 -> 29.840533 | H14: =H8*'Допущения'!$B$8 -> 33.5706 | I14: =I8*'Допущения'!$B$8 -> 35.435633 | ... M14: =M8*'Допущения'!$B$8 -> 50.3559 | N14: =SUM(B14:M14) -> 376.73673
A15: Итого расходы | B15: =SUM(B10:B14) -> 2613.0552 | C15: =SUM(C10:C14) -> 2616.7853 | D15: =SUM(D10:D14) -> 2620.5154 | E15: =SUM(E10:E14) -> 2922.3804 | F15: =SUM(F10:F14) -> 3026.1105 | G15: =SUM(G10:G14) -> 3029.8405 | H15: =SUM(H10:H14) -> 3033.5706 | I15: =SUM(I10:I14) -> 3085.4356 | ... M15: =SUM(M10:M14) -> 3200.3559 | N15: =SUM(B15:M15) -> 35526.737
A16: Операционная прибыль | B16: =B8-B15 -> -2146.7969 | C16: =C8-C15 -> -2017.3103 | D16: =D8-D15 -> -1887.8237 | E16: =E8-E15 -> -2123.0804 | F16: =F8-F15 -> -2093.5938 | G16: =G8-G15 -> -1964.1072 | H16: =H8-H15 -> -1834.6206 | I16: =I8-I15 -> -1819.8773 | ... M16: =M8-M15 -> -1401.9309 | N16: =SUM(B16:M16) -> -22071.853
A17: Первоначальные инвестиции | B17: ='Допущения'!$B$9 -> 12000 | C17: 0 | D17: 0 | E17: 0 | F17: 0 | G17: 0 | H17: 0 | I17: 0 | J17: 0 | K17: 0 | L17: 0 | M17: 0 | N17: =SUM(B17:M17) -> 12000
A18: Чистый денежный поток | B18: =B16-B17 -> -14146.797 | C18: =C16-C17 -> -2017.3103 | D18: =D16-D17 -> -1887.8237 | E18: =E16-E17 -> -2123.0804 | F18: =F16-F17 -> -2093.5938 | G18: =G16-G17 -> -1964.1072 | H18: =H16-H17 -> -1834.6206 | I18: =I16-I17 -> -1819.8773 | ... M18: =M16-M17 -> -1401.9309 | N18: =SUM(B18:M18) -> -34071.853
A19: Накопленный денежный поток | B19: =B18 -> -14146.797 | C19: =B19+C18 -> -16164.107 | D19: =C19+D18 -> -18051.931 | E19: =D19+E18 -> -20175.011 | F19: =E19+F18 -> -22268.605 | G19: =F19+G18 -> -24232.712 | H19: =G19+H18 -> -26067.333 | I19: =H19+I18 -> -27887.21 | J19: =I19+J18 -> -29577.601 | ... M19: =L19+M18 -> -34071.853 | N19: =M19 -> -34071.853
A20: Флаг: операционная прибыль ≥ 0 | B20: =IF(B16>=0, 1, 0) -> 0 | C20: =IF(C16>=0, 1, 0) -> 0 | D20: =IF(D16>=0, 1, 0) -> 0 | E20: =IF(E16>=0, 1, 0) -> 0 | F20: =IF(F16>=0, 1, 0) -> 0 | G20: =IF(G16>=0, 1, 0) -> 0 | H20: =IF(H16>=0, 1, 0) -> 0 | I20: =IF(I16>=0, 1, 0) -> 0 | ... M20: =IF(M16>=0, 1, 0) -> 0
A21: Флаг: накопленный поток ≥ 0 | B21: =IF(B19>=0, 1, 0) -> 0 | C21: =IF(C19>=0, 1, 0) -> 0 | D21: =IF(D19>=0, 1, 0) -> 0 | E21: =IF(E19>=0, 1, 0) -> 0 | F21: =IF(F19>=0, 1, 0) -> 0 | G21: =IF(G19>=0, 1, 0) -> 0 | H21: =IF(H19>=0, 1, 0) -> 0 | I21: =IF(I19>=0, 1, 0) -> 0 | ... M21: =IF(M19>=0, 1, 0) -> 0

Sheet План_Базовый
A1: Помесячный план: Базовый сценарий
A2: Все ячейки считаются формулами из листа «Допущения». Суммы в рублях.
A3: Показатель | B3: Мес. 1 | C3: Мес. 2 | D3: Мес. 3 | E3: Мес. 4 | F3: Мес. 5 | G3: Мес. 6 | H3: Мес. 7 | I3: Мес. 8 | J3: Мес. 9 | K3: Мес. 10 | L3: Мес. 11 | M3: Мес. 12 | N3: Итого / конец
A4: Новые регистрации | B4: ='Допущения'!C21 -> 500 | C4: ='Допущения'!C22 -> 130 | D4: ='Допущения'!C23 -> 130 | E4: ='Допущения'!C24 -> 150 | F4: ='Допущения'!C25 -> 160 | G4: ='Допущения'!C26 -> 160 | H4: ='Допущения'!C27 -> 130 | I4: ='Допущения'!C28 -> 150 | J4: ='Допущения'!C29 -> 150 | K4: ='Допущения'!C30 -> 170 | L4: ='Допущения'!C31 -> 180 | M4: ='Допущения'!C32 -> 190 | N4: =SUM(B4:M4) -> 2200
A5: Всего регистраций | B5: =B4 -> 500 | C5: =B5+C4 -> 630 | D5: =C5+D4 -> 760 | E5: =D5+E4 -> 910 | F5: =E5+F4 -> 1070 | G5: =F5+G4 -> 1230 | H5: =G5+H4 -> 1360 | I5: =H5+I4 -> 1510 | J5: =I5+J4 -> 1660 | ... M5: =L5+M4 -> 2200 | N5: =M5 -> 2200
A6: MAU (активные) | B6: =ROUND(B5*'Допущения'!C14, 0) -> 200 | C6: =ROUND(C5*'Допущения'!C14, 0) -> 252 | D6: =ROUND(D5*'Допущения'!C14, 0) -> 304 | E6: =ROUND(E5*'Допущения'!C14, 0) -> 364 | F6: =ROUND(F5*'Допущения'!C14, 0) -> 428 | G6: =ROUND(G5*'Допущения'!C14, 0) -> 492 | H6: =ROUND(H5*'Допущения'!C14, 0) -> 544 | I6: =ROUND(I5*'Допущения'!C14, 0) -> 604 | J6: =ROUND(J5*'Допущения'!C14, 0) -> 664 | K6: =ROUND(K5*'Допущения'!C14, 0) -> 732 | L6: =ROUND(L5*'Допущения'!C14, 0) -> 804 | M6: =ROUND(M5*'Допущения'!C14, 0) -> 880 | N6: =M6 -> 880
A7: Платящие пользователи | B7: =ROUND(B6*'Допущения'!C15, 0) -> 30 | C7: =ROUND(C6*'Допущения'!C15, 0) -> 38 | D7: =ROUND(D6*'Допущения'!C15, 0) -> 46 | E7: =ROUND(E6*'Допущения'!C15, 0) -> 55 | F7: =ROUND(F6*'Допущения'!C15, 0) -> 64 | G7: =ROUND(G6*'Допущения'!C15, 0) -> 74 | H7: =ROUND(H6*'Допущения'!C15, 0) -> 82 | I7: =ROUND(I6*'Допущения'!C15, 0) -> 91 | J7: =ROUND(J6*'Допущения'!C15, 0) -> 100 | K7: =ROUND(K6*'Допущения'!C15, 0) -> 110 | L7: =ROUND(L6*'Допущения'!C15, 0) -> 121 | M7: =ROUND(M6*'Допущения'!C15, 0) -> 132 | N7: =M7 -> 132
A8: Выручка | B8: =B7*'Допущения'!$B$7 -> 1998.25 | C8: =C7*'Допущения'!$B$7 -> 2531.1167 | D8: =D7*'Допущения'!$B$7 -> 3063.9833 | E8: =E7*'Допущения'!$B$7 -> 3663.4583 | F8: =F7*'Допущения'!$B$7 -> 4262.9333 | G8: =G7*'Допущения'!$B$7 -> 4929.0167 | H8: =H7*'Допущения'!$B$7 -> 5461.8833 | I8: =I7*'Допущения'!$B$7 -> 6061.3583 | ... M8: =M7*'Допущения'!$B$7 -> 8792.3 | N8: =SUM(B8:M8) -> 62811.658
A9: Расходы
A10: Хостинг | B10: ='Допущения'!$B$10 -> 500 | C10: ='Допущения'!$B$10 -> 500 | D10: ='Допущения'!$B$10 -> 500 | E10: ='Допущения'!$B$10 -> 500 | F10: ='Допущения'!$B$10 -> 500 | G10: ='Допущения'!$B$10 -> 500 | H10: ='Допущения'!$B$10 -> 500 | I10: ='Допущения'!$B$10 -> 500 | ... M10: ='Допущения'!$B$10 -> 500 | N10: =SUM(B10:M10) -> 6000
A11: Реклама | B11: =IF(1<=3, 'Допущения'!$B$11, 'Допущения'!C16) -> 2000 | C11: =IF(2<=3, 'Допущения'!$B$11, 'Допущения'!C16) -> 2000 | D11: =IF(3<=3, 'Допущения'!$B$11, 'Допущения'!C16) -> 2000 | E11: =IF(4<=3, 'Допущения'!$B$11, 'Допущения'!C16) -> 3000 | F11: =IF(5<=3, 'Допущения'!$B$11, 'Допущения'!C16) -> 3000 | G11: =IF(6<=3, 'Допущения'!$B$11, 'Допущения'!C16) -> 3000 | H11: =IF(7<=3, 'Допущения'!$B$11, 'Допущения'!C16) -> 3000 | I11: =IF(8<=3, 'Допущения'!$B$11, 'Допущения'!C16) -> 3000 | J11: =IF(9<=3, 'Допущения'!$B$11, 'Допущения'!C16) -> 3000 | K11: =IF(10<=3, 'Допущения'!$B$11, 'Допущения'!C16) -> 3000 | L11: =IF(11<=3, 'Допущения'!$B$11, 'Допущения'!C16) -> 3000 | M11: =IF(12<=3, 'Допущения'!$B$11, 'Допущения'!C16) -> 3000 | N11: =SUM(B11:M11) -> 33000
A12: SMS-верификация | B12: ='Допущения'!B36 -> 100 | C12: ='Допущения'!B37 -> 100 | D12: ='Допущения'!B38 -> 100 | E12: ='Допущения'!B39 -> 200 | F12: ='Допущения'!B40 -> 200 | G12: ='Допущения'!B41 -> 200 | H12: ='Допущения'!B42 -> 200 | I12: ='Допущения'!B43 -> 250 | J12: ='Допущения'!B44 -> 250 | K12: ='Допущения'!B45 -> 300 | L12: ='Допущения'!B46 -> 300 | M12: ='Допущения'!B47 -> 350 | N12: =SUM(B12:M12) -> 2550
A13: API LLM | B13: ='Допущения'!C36 -> 0 | C13: ='Допущения'!C37 -> 0 | D13: ='Допущения'!C38 -> 0 | E13: ='Допущения'!C39 -> 200 | F13: ='Допущения'!C40 -> 300 | G13: ='Допущения'!C41 -> 300 | H13: ='Допущения'!C42 -> 300 | I13: ='Допущения'!C43 -> 300 | J13: ='Допущения'!C44 -> 300 | K13: ='Допущения'!C45 -> 300 | L13: ='Допущения'!C46 -> 300 | M13: ='Допущения'!C47 -> 300 | N13: =SUM(B13:M13) -> 2600
A14: Комиссия ЮKassa | B14: =B8*'Допущения'!$B$8 -> 55.951 | C14: =C8*'Допущения'!$B$8 -> 70.871267 | D14: =D8*'Допущения'!$B$8 -> 85.791533 | E14: =E8*'Допущения'!$B$8 -> 102.57683 | F14: =F8*'Допущения'!$B$8 -> 119.36213 | G14: =G8*'Допущения'!$B$8 -> 138.01247 | H14: =H8*'Допущения'!$B$8 -> 152.93273 | I14: =I8*'Допущения'!$B$8 -> 169.71803 | ... M14: =M8*'Допущения'!$B$8 -> 246.1844 | N14: =SUM(B14:M14) -> 1758.7264
A15: Итого расходы | B15: =SUM(B10:B14) -> 2655.951 | C15: =SUM(C10:C14) -> 2670.8713 | D15: =SUM(D10:D14) -> 2685.7915 | E15: =SUM(E10:E14) -> 4002.5768 | F15: =SUM(F10:F14) -> 4119.3621 | G15: =SUM(G10:G14) -> 4138.0125 | H15: =SUM(H10:H14) -> 4152.9327 | I15: =SUM(I10:I14) -> 4219.718 | ... M15: =SUM(M10:M14) -> 4396.1844 | N15: =SUM(B15:M15) -> 45908.726
A16: Операционная прибыль | B16: =B8-B15 -> -657.701 | C16: =C8-C15 -> -139.7546 | D16: =D8-D15 -> 378.1918 | E16: =E8-E15 -> -339.1185 | F16: =F8-F15 -> 143.5712 | G16: =G8-G15 -> 791.0042 | H16: =H8-H15 -> 1308.9506 | I16: =I8-I15 -> 1841.6403 | ... M16: =M8-M15 -> 4396.1156 | N16: =SUM(B16:M16) -> 16902.932
A17: Первоначальные инвестиции | B17: ='Допущения'!$B$9 -> 12000 | C17: 0 | D17: 0 | E17: 0 | F17: 0 | G17: 0 | H17: 0 | I17: 0 | J17: 0 | K17: 0 | L17: 0 | M17: 0 | N17: =SUM(B17:M17) -> 12000
A18: Чистый денежный поток | B18: =B16-B17 -> -12657.701 | C18: =C16-C17 -> -139.7546 | D18: =D16-D17 -> 378.1918 | E18: =E16-E17 -> -339.1185 | F18: =F16-F17 -> 143.5712 | G18: =G16-G17 -> 791.0042 | H18: =H16-H17 -> 1308.9506 | I18: =I16-I17 -> 1841.6403 | ... M18: =M16-M17 -> 4396.1156 | N18: =SUM(B18:M18) -> 4902.9319
A19: Накопленный денежный поток | B19: =B18 -> -12657.701 | C19: =B19+C18 -> -12797.456 | D19: =C19+D18 -> -12419.264 | E19: =D19+E18 -> -12758.382 | F19: =E19+F18 -> -12614.811 | G19: =F19+G18 -> -11823.807 | H19: =G19+H18 -> -10514.856 | I19: =H19+I18 -> -8673.216 | J19: =I19+J18 -> -6248.886 | ... M19: =L19+M18 -> 4902.9319 | N19: =M19 -> 4902.9319
A20: Флаг: операционная прибыль ≥ 0 | B20: =IF(B16>=0, 1, 0) -> 0 | C20: =IF(C16>=0, 1, 0) -> 0 | D20: =IF(D16>=0, 1, 0) -> 1 | E20: =IF(E16>=0, 1, 0) -> 0 | F20: =IF(F16>=0, 1, 0) -> 1 | G20: =IF(G16>=0, 1, 0) -> 1 | H20: =IF(H16>=0, 1, 0) -> 1 | I20: =IF(I16>=0, 1, 0) -> 1 | ... M20: =IF(M16>=0, 1, 0) -> 1
A21: Флаг: накопленный поток ≥ 0 | B21: =IF(B19>=0, 1, 0) -> 0 | C21: =IF(C19>=0, 1, 0) -> 0 | D21: =IF(D19>=0, 1, 0) -> 0 | E21: =IF(E19>=0, 1, 0) -> 0 | F21: =IF(F19>=0, 1, 0) -> 0 | G21: =IF(G19>=0, 1, 0) -> 0 | H21: =IF(H19>=0, 1, 0) -> 0 | I21: =IF(I19>=0, 1, 0) -> 0 | ... M21: =IF(M19>=0, 1, 0) -> 1

Sheet План_Оптимистичный
A1: Помесячный план: Оптимистичный сценарий
A2: Все ячейки считаются формулами из листа «Допущения». Суммы в рублях.
A3: Показатель | B3: Мес. 1 | C3: Мес. 2 | D3: Мес. 3 | E3: Мес. 4 | F3: Мес. 5 | G3: Мес. 6 | H3: Мес. 7 | I3: Мес. 8 | J3: Мес. 9 | K3: Мес. 10 | L3: Мес. 11 | M3: Мес. 12 | N3: Итого / конец
A4: Новые регистрации | B4: ='Допущения'!D21 -> 700 | C4: ='Допущения'!D22 -> 200 | D4: ='Допущения'!D23 -> 200 | E4: ='Допущения'!D24 -> 250 | F4: ='Допущения'!D25 -> 280 | G4: ='Допущения'!D26 -> 280 | H4: ='Допущения'!D27 -> 230 | I4: ='Допущения'!D28 -> 280 | J4: ='Допущения'!D29 -> 280 | K4: ='Допущения'!D30 -> 310 | L4: ='Допущения'!D31 -> 330 | M4: ='Допущения'!D32 -> 350 | N4: =SUM(B4:M4) -> 3690
A5: Всего регистраций | B5: =B4 -> 700 | C5: =B5+C4 -> 900 | D5: =C5+D4 -> 1100 | E5: =D5+E4 -> 1350 | F5: =E5+F4 -> 1630 | G5: =F5+G4 -> 1910 | H5: =G5+H4 -> 2140 | I5: =H5+I4 -> 2420 | J5: =I5+J4 -> 2700 | ... M5: =L5+M4 -> 3690 | N5: =M5 -> 3690
A6: MAU (активные) | B6: =ROUND(B5*'Допущения'!D14, 0) -> 350 | C6: =ROUND(C5*'Допущения'!D14, 0) -> 450 | D6: =ROUND(D5*'Допущения'!D14, 0) -> 550 | E6: =ROUND(E5*'Допущения'!D14, 0) -> 675 | F6: =ROUND(F5*'Допущения'!D14, 0) -> 815 | G6: =ROUND(G5*'Допущения'!D14, 0) -> 955 | H6: =ROUND(H5*'Допущения'!D14, 0) -> 1070 | I6: =ROUND(I5*'Допущения'!D14, 0) -> 1210 | J6: =ROUND(J5*'Допущения'!D14, 0) -> 1350 | K6: =ROUND(K5*'Допущения'!D14, 0) -> 1505 | L6: =ROUND(L5*'Допущения'!D14, 0) -> 1670 | M6: =ROUND(M5*'Допущения'!D14, 0) -> 1845 | N6: =M6 -> 1845
A7: Платящие пользователи | B7: =ROUND(B6*'Допущения'!D15, 0) -> 77 | C7: =ROUND(C6*'Допущения'!D15, 0) -> 99 | D7: =ROUND(D6*'Допущения'!D15, 0) -> 121 | E7: =ROUND(E6*'Допущения'!D15, 0) -> 149 | F7: =ROUND(F6*'Допущения'!D15, 0) -> 179 | G7: =ROUND(G6*'Допущения'!D15, 0) -> 210 | H7: =ROUND(H6*'Допущения'!D15, 0) -> 235 | I7: =ROUND(I6*'Допущения'!D15, 0) -> 266 | J7: =ROUND(J6*'Допущения'!D15, 0) -> 297 | K7: =ROUND(K6*'Допущения'!D15, 0) -> 331 | L7: =ROUND(L6*'Допущения'!D15, 0) -> 367 | M7: =ROUND(M6*'Допущения'!D15, 0) -> 406 | N7: =M7 -> 406
A8: Выручка | B8: =B7*'Допущения'!$B$7 -> 5128.8417 | C8: =C7*'Допущения'!$B$7 -> 6594.225 | D8: =D7*'Допущения'!$B$7 -> 8059.6083 | E8: =E7*'Допущения'!$B$7 -> 9924.6417 | F8: =F7*'Допущения'!$B$7 -> 11922.892 | G8: =G7*'Допущения'!$B$7 -> 13987.75 | H8: =H7*'Допущения'!$B$7 -> 15652.958 | I8: =I7*'Допущения'!$B$7 -> 17717.817 | ... M8: =M7*'Допущения'!$B$7 -> 27042.983 | N8: =SUM(B8:M8) -> 182307.01
A9: Расходы
A10: Хостинг | B10: ='Допущения'!$B$10 -> 500 | C10: ='Допущения'!$B$10 -> 500 | D10: ='Допущения'!$B$10 -> 500 | E10: ='Допущения'!$B$10 -> 500 | F10: ='Допущения'!$B$10 -> 500 | G10: ='Допущения'!$B$10 -> 500 | H10: ='Допущения'!$B$10 -> 500 | I10: ='Допущения'!$B$10 -> 500 | ... M10: ='Допущения'!$B$10 -> 500 | N10: =SUM(B10:M10) -> 6000
A11: Реклама | B11: =IF(1<=3, 'Допущения'!$B$11, 'Допущения'!D16) -> 2000 | C11: =IF(2<=3, 'Допущения'!$B$11, 'Допущения'!D16) -> 2000 | D11: =IF(3<=3, 'Допущения'!$B$11, 'Допущения'!D16) -> 2000 | E11: =IF(4<=3, 'Допущения'!$B$11, 'Допущения'!D16) -> 5000 | F11: =IF(5<=3, 'Допущения'!$B$11, 'Допущения'!D16) -> 5000 | G11: =IF(6<=3, 'Допущения'!$B$11, 'Допущения'!D16) -> 5000 | H11: =IF(7<=3, 'Допущения'!$B$11, 'Допущения'!D16) -> 5000 | I11: =IF(8<=3, 'Допущения'!$B$11, 'Допущения'!D16) -> 5000 | J11: =IF(9<=3, 'Допущения'!$B$11, 'Допущения'!D16) -> 5000 | K11: =IF(10<=3, 'Допущения'!$B$11, 'Допущения'!D16) -> 5000 | L11: =IF(11<=3, 'Допущения'!$B$11, 'Допущения'!D16) -> 5000 | M11: =IF(12<=3, 'Допущения'!$B$11, 'Допущения'!D16) -> 5000 | N11: =SUM(B11:M11) -> 51000
A12: SMS-верификация | B12: ='Допущения'!B36 -> 100 | C12: ='Допущения'!B37 -> 100 | D12: ='Допущения'!B38 -> 100 | E12: ='Допущения'!B39 -> 200 | F12: ='Допущения'!B40 -> 200 | G12: ='Допущения'!B41 -> 200 | H12: ='Допущения'!B42 -> 200 | I12: ='Допущения'!B43 -> 250 | J12: ='Допущения'!B44 -> 250 | K12: ='Допущения'!B45 -> 300 | L12: ='Допущения'!B46 -> 300 | M12: ='Допущения'!B47 -> 350 | N12: =SUM(B12:M12) -> 2550
A13: API LLM | B13: ='Допущения'!C36 -> 0 | C13: ='Допущения'!C37 -> 0 | D13: ='Допущения'!C38 -> 0 | E13: ='Допущения'!C39 -> 200 | F13: ='Допущения'!C40 -> 300 | G13: ='Допущения'!C41 -> 300 | H13: ='Допущения'!C42 -> 300 | I13: ='Допущения'!C43 -> 300 | J13: ='Допущения'!C44 -> 300 | K13: ='Допущения'!C45 -> 300 | L13: ='Допущения'!C46 -> 300 | M13: ='Допущения'!C47 -> 300 | N13: =SUM(B13:M13) -> 2600
A14: Комиссия ЮKassa | B14: =B8*'Допущения'!$B$8 -> 143.60757 | C14: =C8*'Допущения'!$B$8 -> 184.6383 | D14: =D8*'Допущения'!$B$8 -> 225.66903 | E14: =E8*'Допущения'!$B$8 -> 277.88997 | F14: =F8*'Допущения'!$B$8 -> 333.84097 | G14: =G8*'Допущения'!$B$8 -> 391.657 | H14: =H8*'Допущения'!$B$8 -> 438.28283 | I14: =I8*'Допущения'!$B$8 -> 496.09887 | ... M14: =M8*'Допущения'!$B$8 -> 757.20353 | N14: =SUM(B14:M14) -> 5104.5962
A15: Итого расходы | B15: =SUM(B10:B14) -> 2743.6076 | C15: =SUM(C10:C14) -> 2784.6383 | D15: =SUM(D10:D14) -> 2825.669 | E15: =SUM(E10:E14) -> 6177.89 | F15: =SUM(F10:F14) -> 6333.841 | G15: =SUM(G10:G14) -> 6391.657 | H15: =SUM(H10:H14) -> 6438.2828 | I15: =SUM(I10:I14) -> 6546.0989 | ... M15: =SUM(M10:M14) -> 6907.2035 | N15: =SUM(B15:M15) -> 67254.596
A16: Операционная прибыль | B16: =B8-B15 -> 2385.2341 | C16: =C8-C15 -> 3809.5867 | D16: =D8-D15 -> 5233.9393 | E16: =E8-E15 -> 3746.7517 | F16: =F8-F15 -> 5589.0507 | G16: =G8-G15 -> 7596.093 | H16: =H8-H15 -> 9214.6755 | I16: =I8-I15 -> 11171.718 | ... M16: =M8-M15 -> 20135.78 | N16: =SUM(B16:M16) -> 115052.41
A17: Первоначальные инвестиции | B17: ='Допущения'!$B$9 -> 12000 | C17: 0 | D17: 0 | E17: 0 | F17: 0 | G17: 0 | H17: 0 | I17: 0 | J17: 0 | K17: 0 | L17: 0 | M17: 0 | N17: =SUM(B17:M17) -> 12000
A18: Чистый денежный поток | B18: =B16-B17 -> -9614.7659 | C18: =C16-C17 -> 3809.5867 | D18: =D16-D17 -> 5233.9393 | E18: =E16-E17 -> 3746.7517 | F18: =F16-F17 -> 5589.0507 | G18: =G16-G17 -> 7596.093 | H18: =H16-H17 -> 9214.6755 | I18: =I16-I17 -> 11171.718 | ... M18: =M16-M17 -> 20135.78 | N18: =SUM(B18:M18) -> 103052.41
A19: Накопленный денежный поток | B19: =B18 -> -9614.7659 | C19: =B19+C18 -> -5805.1792 | D19: =C19+D18 -> -571.2399 | E19: =D19+E18 -> 3175.5118 | F19: =E19+F18 -> 8764.5625 | G19: =F19+G18 -> 16360.656 | H19: =G19+H18 -> 25575.331 | I19: =H19+I18 -> 36747.049 | J19: =I19+J18 -> 49925.809 | ... M19: =L19+M18 -> 103052.41 | N19: =M19 -> 103052.41
A20: Флаг: операционная прибыль ≥ 0 | B20: =IF(B16>=0, 1, 0) -> 1 | C20: =IF(C16>=0, 1, 0) -> 1 | D20: =IF(D16>=0, 1, 0) -> 1 | E20: =IF(E16>=0, 1, 0) -> 1 | F20: =IF(F16>=0, 1, 0) -> 1 | G20: =IF(G16>=0, 1, 0) -> 1 | H20: =IF(H16>=0, 1, 0) -> 1 | I20: =IF(I16>=0, 1, 0) -> 1 | ... M20: =IF(M16>=0, 1, 0) -> 1
A21: Флаг: накопленный поток ≥ 0 | B21: =IF(B19>=0, 1, 0) -> 0 | C21: =IF(C19>=0, 1, 0) -> 0 | D21: =IF(D19>=0, 1, 0) -> 0 | E21: =IF(E19>=0, 1, 0) -> 1 | F21: =IF(F19>=0, 1, 0) -> 1 | G21: =IF(G19>=0, 1, 0) -> 1 | H21: =IF(H19>=0, 1, 0) -> 1 | I21: =IF(I19>=0, 1, 0) -> 1 | ... M21: =IF(M19>=0, 1, 0) -> 1

Sheet Маржа и безубыточность
A1: Маржинальность, точка безубыточности, юнит-экономика
A2: Считается по трём сценариям из листов «План_…». Суммы в рублях.
A3: Показатель | B3: Пессимистичный | C3: Базовый | D3: Оптимистичный | E3: Как считается
A4: 1. Маржинальность на одного платящего
A5: ARPU, руб. в месяц | B5: ='Допущения'!$B$7 -> 66.608333 | C5: ='Допущения'!$B$7 -> 66.608333 | D5: ='Допущения'!$B$7 -> 66.608333 | E5: Средний доход с платящего пользователя
A6: Переменные расходы на платящего, руб. | B6: ='Допущения'!$B$7*'Допущения'!$B$8 -> 1.8650333 | C6: ='Допущения'!$B$7*'Допущения'!$B$8 -> 1.8650333 | D6: ='Допущения'!$B$7*'Допущения'!$B$8 -> 1.8650333 | E6: Комиссия ЮKassa; остальное считается постоянным
A7: Маржа на платящего (вклад), руб. | B7: =B5-B6 -> 64.7433 | C7: =C5-C6 -> 64.7433 | D7: =D5-D6 -> 64.7433 | E7: ARPU минус переменные расходы
A8: Маржинальность, % | B8: =B7/B5 -> 0.972 | C8: =C7/C5 -> 0.972 | D8: =D7/D5 -> 0.972 | E8: Маржа / ARPU
A10: 2. Точка безубыточности (в месяц)
A11: Постоянные расходы, мес. 1–3, руб./мес | B11: =SUM('План_Пессимистичный'!B10:D13)/3 -> 2600 | C11: =SUM('План_Базовый'!B10:D13)/3 -> 2600 | D11: =SUM('План_Оптимистичный'!B10:D13)/3 -> 2600 | E11: Хостинг + реклама + SMS + LLM, среднее за мес. 1–3
A12: Постоянные расходы, мес. 4–12, руб./мес | B12: =SUM('План_Пессимистичный'!E10:M13)/9 -> 3038.8889 | C12: =SUM('План_Базовый'!E10:M13)/9 -> 4038.8889 | D12: =SUM('План_Оптимистичный'!E10:M13)/9 -> 6038.8889 | E12: То же, среднее за мес. 4–12
A13: Безубыточность, мес. 1–3, платящих | B13: =ROUNDUP(B11/B7, 0) -> 41 | C13: =ROUNDUP(C11/C7, 0) -> 41 | D13: =ROUNDUP(D11/D7, 0) -> 41 | E13: Постоянные расходы / маржа на платящего
A14: Безубыточность, мес. 4–12, платящих | B14: =ROUNDUP(B12/B7, 0) -> 47 | C14: =ROUNDUP(C12/C7, 0) -> 63 | D14: =ROUNDUP(D12/D7, 0) -> 94 | E14: Постоянные расходы / маржа на платящего
A15: Безубыточность, мес. 4–12, выручка руб./мес | B15: =B12/B8 -> 3126.4289 | C15: =C12/C8 -> 4155.2355 | D15: =D12/D8 -> 6212.8487 | E15: Постоянные расходы / маржинальность
A16: Платящих в конце 12-го месяца | B16: ='План_Пессимистичный'!M7 -> 27 | C16: ='План_Базовый'!M7 -> 132 | D16: ='План_Оптимистичный'!M7 -> 406 | E16: Из плана сценария
A17: Запас прочности, % | B17: =IF(B16=0, 0, (B16-B14)/B16) -> -0.74074074 | C17: =IF(C16=0, 0, (C16-C14)/C16) -> 0.52272727 | D17: =IF(D16=0, 0, (D16-D14)/D16) -> 0.76847291 | E17: На сколько можно потерять платящих до убытка (<0 = уже убыток)
A18: Нужная конверсия MAU / платящие, % | B18: =IF('План_Пессимистичный'!M6=0, 0, B14/'План_Пессимистичный'!M6) -> 0.13988095 | C18: =IF('План_Базовый'!M6=0, 0, C14/'План_Базовый'!M6) -> 0.071590909 | D18: =IF('План_Оптимистичный'!M6=0, 0, D14/'План_Оптимистичный'!M6) -> 0.050948509 | E18: Безубыточное число платящих / MAU на конец года
A19: Первый месяц с операционной прибылью | B19: =IFERROR(MATCH(1, 'План_Пессимистичный'!B20:M20, 0), "не достигается") -> не достигается | C19: =IFERROR(MATCH(1, 'План_Базовый'!B20:M20, 0), "не достигается") -> 3 | D19: =IFERROR(MATCH(1, 'План_Оптимистичный'!B20:M20, 0), "не достигается") -> 1 | E19: Первый месяц, где выручка ≥ расходов
A20: Месяц окупаемости (с инвестициями) | B20: =IFERROR(MATCH(1, 'План_Пессимистичный'!B21:M21, 0), "не за 12 мес.") -> не за 12 мес. | C20: =IFERROR(MATCH(1, 'План_Базовый'!B21:M21, 0), "не за 12 мес.") -> 11 | D20: =IFERROR(MATCH(1, 'План_Оптимистичный'!B21:M21, 0), "не за 12 мес.") -> 4 | E20: Первый месяц, где накопленный поток ≥ 0
A22: 3. Итоги года и юнит-экономика
A23: Выручка за 12 мес., руб. | B23: ='План_Пессимистичный'!N8 -> 13454.883 | C23: ='План_Базовый'!N8 -> 62811.658 | D23: ='План_Оптимистичный'!N8 -> 182307.01 | E23: Сумма по плану
A24: Расходы за 12 мес., руб. | B24: ='План_Пессимистичный'!N15 -> 35526.737 | C24: ='План_Базовый'!N15 -> 45908.726 | D24: ='План_Оптимистичный'!N15 -> 67254.596 | E24: Сумма по плану
A25: Операционная прибыль, руб. | B25: =B23-B24 -> -22071.853 | C25: =C23-C24 -> 16902.932 | D25: =D23-D24 -> 115052.41 | E25: Выручка минус расходы
A26: Чистая маржа, % | B26: =IF(B23=0, 0, B25/B23) -> -1.6404344 | C26: =IF(C23=0, 0, C25/C23) -> 0.26910501 | D26: =IF(D23=0, 0, D25/D23) -> 0.63109155 | E26: Прибыль / выручка
A27: CAC: реклама / платящие на конец года, руб. | B27: =IF('План_Пессимистичный'!M7=0, 0, 'План_Пессимистичный'!N11/'План_Пессимистичный'!M7) -> 888.88889 | C27: =IF('План_Базовый'!M7=0, 0, 'План_Базовый'!N11/'План_Базовый'!M7) -> 250 | D27: =IF('План_Оптимистичный'!M7=0, 0, 'План_Оптимистичный'!N11/'План_Оптимистичный'!M7) -> 125.61576 | E27: Стоимость привлечения одного платящего (упрощённо)
A28: Время жизни годового подписчика, мес. | B28: =1/'Допущения'!B18 -> 25 | C28: =1/'Допущения'!C18 -> 25 | D28: =1/'Допущения'!D18 -> 25 | E28: 1 / отток
A29: Время жизни месячного подписчика, мес. | B29: =1/'Допущения'!B17 -> 6.6666667 | C29: =1/'Допущения'!C17 -> 10 | D29: =1/'Допущения'!D17 -> 14.285714 | E29: 1 / отток
A30: LTV (после комиссии), руб. | B30: =('Допущения'!$B$6*'Допущения'!$B$4/12*B28+(1-'Допущения'!$B$6)*'Допущения'!$B$5*B29)*(1-'Допущения'!$B$8) -> 1001.1195 | C30: =('Допущения'!$B$6*'Допущения'!$B$4/12*C28+(1-'Допущения'!$B$6)*'Допущения'!$B$5*C29)*(1-'Допущения'!$B$8) -> 1113.3855 | D30: =('Допущения'!$B$6*'Допущения'!$B$4/12*D28+(1-'Допущения'!$B$6)*'Допущения'!$B$5*D29)*(1-'Допущения'!$B$8) -> 1257.7275 | E30: Доход за время жизни по каждому типу подписки, минус комиссия
A31: LTV / CAC | B31: =IF(B27=0, 0, B30/B27) -> 1.1262594 | C31: =IF(C27=0, 0, C30/C27) -> 4.453542 | D31: =IF(D27=0, 0, D30/D27) -> 10.012497 | E31: Ориентир: больше 3 - хорошо
A32: Окупаемость CAC, мес. | B32: =IF(B7=0, 0, B27/B7) -> 13.729434 | C32: =IF(C7=0, 0, C27/C7) -> 3.8614034 | D32: =IF(D7=0, 0, D27/D7) -> 1.9402126 | E32: CAC / маржа на платящего в месяц
